Workbook

Sheet State Mapping
A1: Abbrev | B1: Full State Name
A2: AK | B2: Alaska
A3: AL | B3: Alabama
A4: AR | B4: Arkansas
A5: AZ | B5: Arizona
A6: CA | B6: California
A7: CO | B7: Colorado
A8: CT | B8: Connecticut
A9: DC | B9: District of Columbia
A10: DE | B10: Delaware
A11: FL | B11: Florida
A12: GA | B12: Georgia
... A53: WY | B53: Wyoming

Sheet State Premium Data
A1: state | B1: earnings_hs | C1: earnings_bachelors | D1: premium_dollars | E1: premium_ratio | F1: premium_pct | G1: cost_of_living_index
A2: District of Columbia | B2: 40715 | C2: 95628 | D2: 54913 | E2: 2.35 | F2: 135 | G2: 109.9
A3: New Jersey | B3: 41528 | C3: 80114 | D3: 38586 | E3: 1.93 | F3: 93 | G3: 108.8
A4: California | B4: 40803 | C4: 78278 | D4: 37475 | E4: 1.92 | F4: 92 | G4: 110.7
A5: New York | B5: 39771 | C5: 74504 | D5: 34733 | E5: 1.87 | F5: 87 | G5: 107.9
A6: Massachusetts | B6: 43761 | C6: 79985 | D6: 36224 | E6: 1.83 | F6: 83 | G6: 105.8
A7: Virginia | B7: 41061 | C7: 74468 | D7: 33407 | E7: 1.81 | F7: 81 | G7: 101.1
A8: Puerto Rico | B8: 16957 | C8: 30562 | D8: 13605 | E8: 1.8 | F8: 80
A9: Connecticut | B9: 42120 | C9: 75975 | D9: 33855 | E9: 1.8 | F9: 80 | G9: 103.6
A10: Maryland | B10: 42778 | C10: 76748 | D10: 33970 | E10: 1.79 | F10: 79 | G10: 105
A11: Texas | B11: 37086 | C11: 66474 | D11: 29388 | E11: 1.79 | F11: 79 | G11: 97.1
A12: Illinois | B12: 40285 | C12: 71127 | D12: 30842 | E12: 1.77 | F12: 77 | G12: 100
A13: Michigan | B13: 36823 | C13: 64810 | D13: 27987 | E13: 1.76 | F13: 76 | G13: 96.2
A14: Washington | B14: 44866 | C14: 78485 | D14: 33619 | E14: 1.75 | F14: 75 | G14: 107
A15: Georgia | B15: 36820 | C15: 64185 | D15: 27365 | E15: 1.74 | F15: 74 | G15: 96.3
A16: Colorado | B16: 42541 | C16: 73072 | D16: 30531 | E16: 1.72 | F16: 72 | G16: 103.1
A17: Oregon | B17: 39308 | C17: 67100 | D17: 27792 | E17: 1.71 | F17: 71 | G17: 103.4
A18: Ohio | B18: 37990 | C18: 64933 | D18: 26943 | E18: 1.71 | F18: 71 | G18: 92.8
A19: North Carolina | B19: 36723 | C19: 62338 | D19: 25615 | E19: 1.7 | F19: 70 | G19: 94.3
A20: Minnesota | B20: 42435 | C20: 71254 | D20: 28819 | E20: 1.68 | F20: 68 | G20: 98.6
... A53: Vermont | B53: 43810 | C53: 56741 | D53: 12931 | E53: 1.3 | F53: 30 | G53: 98

Sheet College Data
A1: University | B1: State | C1: City | D1: Admission Rate (%) | E1: Average SAT | F1: Student Size | G1: In-State Tuition ($) | H1: Out-of-State Tuition ($) | I1: Median Earnings 10yr ($) | J1: Completion Rate (%) | K1: Median Debt ($) | L1: Nobel Prizes | M1: March Madness 2026 | N1: State Full Name | O1: State College Wage Premium ($) | P1: State Baseline Earnings - Bachelors ($) | Q1: Debt-to-Premium Ratio | R1: Real Earnings vs State Baseline ($) | S1: Real Earnings vs State Baseline (%)
A2: Stanford University | B2: CA | C2: Stanford | D2: 3.6 | E2: 1553 | F2: 7554 | G2: 65910 | H2: 65910 | I2: 124080 | J2: 92.4 | K2: 12000 | L2: 22 | M2: No | N2: =INDEX('State Mapping'!$B$2:$B$53,MATCH(B2,'State Mapping'!$A$2:$A$53,0)) -> California | O2: =IFERROR(INDEX('State Premium Data'!$D$2:$D$53,MATCH(N2,'State Premium Data'!$A$2:$A$53,0)),"") -> 37475 | P2: =IFERROR(INDEX('State Premium Data'!$C$2:$C$53,MATCH(N2,'State Premium Data'!$A$2:$A$53,0)),"") -> 78278 | Q2: =IFERROR(K2/O2,"") -> 0.32021348 | R2: =IFERROR(I2-P2,"") -> 45802 | S2: =IFERROR(R2/P2,"") -> 0.5851197
A3: Harvard University | B3: MA | C3: Cambridge | D3: 3.6 | E3: 1553 | F3: 7601 | G3: 61676 | H3: 61676 | I3: 101817 | J3: 97.5 | K3: 14000 | L3: 29 | M3: No | N3: =INDEX('State Mapping'!$B$2:$B$53,MATCH(B3,'State Mapping'!$A$2:$A$53,0)) -> Massachusetts | O3: =IFERROR(INDEX('State Premium Data'!$D$2:$D$53,MATCH(N3,'State Premium Data'!$A$2:$A$53,0)),"") -> 36224 | P3: =IFERROR(INDEX('State Premium Data'!$C$2:$C$53,MATCH(N3,'State Premium Data'!$A$2:$A$53,0)),"") -> 79985 | Q3: =IFERROR(K3/O3,"") -> 0.3864841 | R3: =IFERROR(I3-P3,"") -> 21832 | S3: =IFERROR(R3/P3,"") -> 0.27295118
A4: Yale University | B4: CT | C4: New Haven | D4: 3.9 | E4: 1534 | F4: 6758 | G4: 67250 | H4: 67250 | I4: 100533 | J4: 96 | K4: 12975 | L4: 9 | M4: No | N4: =INDEX('State Mapping'!$B$2:$B$53,MATCH(B4,'State Mapping'!$A$2:$A$53,0)) -> Connecticut | O4: =IFERROR(INDEX('State Premium Data'!$D$2:$D$53,MATCH(N4,'State Premium Data'!$A$2:$A$53,0)),"") -> 33855 | P4: =IFERROR(INDEX('State Premium Data'!$C$2:$C$53,MATCH(N4,'State Premium Data'!$A$2:$A$53,0)),"") -> 75975 | Q4: =IFERROR(K4/O4,"") -> 0.3832521 | R4: =IFERROR(I4-P4,"") -> 24558 | S4: =IFERROR(R4/P4,"") -> 0.32323791
A5: Columbia University in the City of New York | B5: NY | C5: New York | D5: 4 | E5: 1553 | F5: 8973 | G5: 71845 | H5: 71845 | I5: 102491 | J5: 95.5 | K5: 21500 | L5: 18 | M5: No | N5: =INDEX('State Mapping'!$B$2:$B$53,MATCH(B5,'State Mapping'!$A$2:$A$53,0)) -> New York | O5: =IFERROR(INDEX('State Premium Data'!$D$2:$D$53,MATCH(N5,'State Premium Data'!$A$2:$A$53,0)),"") -> 34733 | P5: =IFERROR(INDEX('State Premium Data'!$C$2:$C$53,MATCH(N5,'State Premium Data'!$A$2:$A$53,0)),"") -> 74504 | Q5: =IFERROR(K5/O5,"") -> 0.61900786 | R5: =IFERROR(I5-P5,"") -> 27987 | S5: =IFERROR(R5/P5,"") -> 0.37564426
A6: University of Chicago | B6: IL | C6: Chicago | D6: 4.5 | E6: 1554 | F6: 7569 | G6: 70662 | H6: 70662 | I6: 91885 | J6: 95.4 | K6: 15000 | L6: 20 | M6: No | N6: =INDEX('State Mapping'!$B$2:$B$53,MATCH(B6,'State Mapping'!$A$2:$A$53,0)) -> Illinois | O6: =IFERROR(INDEX('State Premium Data'!$D$2:$D$53,MATCH(N6,'State Premium Data'!$A$2:$A$53,0)),"") -> 30842 | P6: =IFERROR(INDEX('State Premium Data'!$C$2:$C$53,MATCH(N6,'State Premium Data'!$A$2:$A$53,0)),"") -> 71127 | Q6: =IFERROR(K6/O6,"") -> 0.48634978 | R6: =IFERROR(I6-P6,"") -> 20758 | S6: =IFERROR(R6/P6,"") -> 0.29184417
A7: Princeton University | B7: NJ | C7: Princeton | D7: 4.6 | E7: 1553 | F7: 5709 | G7: 62688 | H7: 62688 | I7: 110066 | J7: 97.4 | K7: 10320 | L7: 18 | M7: No | N7: =INDEX('State Mapping'!$B$2:$B$53,MATCH(B7,'State Mapping'!$A$2:$A$53,0)) -> New Jersey | O7: =IFERROR(INDEX('State Premium Data'!$D$2:$D$53,MATCH(N7,'State Premium Data'!$A$2:$A$53,0)),"") -> 38586 | P7: =IFERROR(INDEX('State Premium Data'!$C$2:$C$53,MATCH(N7,'State Premium Data'!$A$2:$A$53,0)),"") -> 80114 | Q7: =IFERROR(K7/O7,"") -> 0.26745452 | R7: =IFERROR(I7-P7,"") -> 29952 | S7: =IFERROR(R7/P7,"") -> 0.37386724
A8: Northeastern University | B8: MA | C8: Boston | D8: 5.2 | E8: 1497 | F8: 17326 | G8: 66162 | H8: 66162 | I8: 92538 | J8: 90.5 | K8: 24250 | L8: 0 | M8: No | N8: =INDEX('State Mapping'!$B$2:$B$53,MATCH(B8,'State Mapping'!$A$2:$A$53,0)) -> Massachusetts | O8: =IFERROR(INDEX('State Premium Data'!$D$2:$D$53,MATCH(N8,'State Premium Data'!$A$2:$A$53,0)),"") -> 36224 | P8: =IFERROR(INDEX('State Premium Data'!$C$2:$C$53,MATCH(N8,'State Premium Data'!$A$2:$A$53,0)),"") -> 79985 | Q8: =IFERROR(K8/O8,"") -> 0.66944567 | R8: =IFERROR(I8-P8,"") -> 12553 | S8: =IFERROR(R8/P8,"") -> 0.15694193
A9: Brown University | B9: RI | C9: Providence | D9: 5.4 | E9: 1546 | F9: 7226 | G9: 71412 | H9: 71412 | I9: 93487 | J9: 95.7 | K9: 11428 | L9: 3 | M9: No | N9: =INDEX('State Mapping'!$B$2:$B$53,MATCH(B9,'State Mapping'!$A$2:$A$53,0)) -> Rhode Island | O9: =IFERROR(INDEX('State Premium Data'!$D$2:$D$53,MATCH(N9,'State Premium Data'!$A$2:$A$53,0)),"") -> 24927 | P9: =IFERROR(INDEX('State Premium Data'!$C$2:$C$53,MATCH(N9,'State Premium Data'!$A$2:$A$53,0)),"") -> 68084 | Q9: =IFERROR(K9/O9,"") -> 0.4584587 | R9: =IFERROR(I9-P9,"") -> 25403 | S9: =IFERROR(R9/P9,"") -> 0.37311263
A10: University of Pennsylvania | B10: PA | C10: Philadelphia | D10: 5.4 | E10: 1553 | F10: 10650 | G10: 68686 | H10: 68686 | I10: 111371 | J10: 96.7 | K10: 15715 | L10: 5 | M10: Yes | N10: =INDEX('State Mapping'!$B$2:$B$53,MATCH(B10,'State Mapping'!$A$2:$A$53,0)) -> Pennsylvania | O10: =IFERROR(INDEX('State Premium Data'!$D$2:$D$53,MATCH(N10,'State Premium Data'!$A$2:$A$53,0)),"") -> 25342 | P10: =IFERROR(INDEX('State Premium Data'!$C$2:$C$53,MATCH(N10,'State Premium Data'!$A$2:$A$53,0)),"") -> 65678 | Q10: =IFERROR(K10/O10,"") -> 0.6201168 | R10: =IFERROR(I10-P10,"") -> 45693 | S10: =IFERROR(R10/P10,"") -> 0.69571242
A11: Duke University | B11: NC | C11: Durham | D11: 5.7 | E11: 1548 | F11: 6442 | G11: 68758 | H11: 68758 | I11: 97800 | J11: 96.3 | K11: 13000 | L11: 0 | M11: Yes | N11: =INDEX('State Mapping'!$B$2:$B$53,MATCH(B11,'State Mapping'!$A$2:$A$53,0)) -> North Carolina | O11: =IFERROR(INDEX('State Premium Data'!$D$2:$D$53,MATCH(N11,'State Premium Data'!$A$2:$A$53,0)),"") -> 25615 | P11: =IFERROR(INDEX('State Premium Data'!$C$2:$C$53,MATCH(N11,'State Premium Data'!$A$2:$A$53,0)),"") -> 62338 | Q11: =IFERROR(K11/O11,"") -> 0.50751513 | R11: =IFERROR(I11-P11,"") -> 35462 | S11: =IFERROR(R11/P11,"") -> 0.5688665
A12: Vanderbilt University | B12: TN | C12: Nashville | D12: 5.9 | E12: 1549 | F12: 7208 | G12: 67498 | H12: 67498 | I12: 91565 | J12: 93.1 | K12: 14000 | L12: 1 | M12: Yes | N12: =INDEX('State Mapping'!$B$2:$B$53,MATCH(B12,'State Mapping'!$A$2:$A$53,0)) -> Tennessee | O12: =IFERROR(INDEX('State Premium Data'!$D$2:$D$53,MATCH(N12,'State Premium Data'!$A$2:$A$53,0)),"") -> 23496 | P12: =IFERROR(INDEX('State Premium Data'!$C$2:$C$53,MATCH(N12,'State Premium Data'!$A$2:$A$53,0)),"") -> 61189 | Q12: =IFERROR(K12/O12,"") -> 0.5958461 | R12: =IFERROR(I12-P12,"") -> 30376 | S12: =IFERROR(R12/P12,"") -> 0.4964291
A13: Johns Hopkins University | B13: MD | C13: Baltimore | D13: 6.4 | E13: 1553 | F13: 5693 | G13: 65230 | H13: 65230 | I13: 87555 | J13: 94.2 | K13: 10250 | L13: 2 | M13: No | N13: =INDEX('State Mapping'!$B$2:$B$53,MATCH(B13,'State Mapping'!$A$2:$A$53,0)) -> Maryland | O13: =IFERROR(INDEX('State Premium Data'!$D$2:$D$53,MATCH(N13,'State Premium Data'!$A$2:$A$53,0)),"") -> 33970 | P13: =IFERROR(INDEX('State Premium Data'!$C$2:$C$53,MATCH(N13,'State Premium Data'!$A$2:$A$53,0)),"") -> 76748 | Q13: =IFERROR(K13/O13,"") -> 0.30173683 | R13: =IFERROR(I13-P13,"") -> 10807 | S13: =IFERROR(R13/P13,"") -> 0.14081149
... A15: Cornell University | B15: NY | C15: Ithaca | D15: 8.8 | E15: 1535 | F15: 15995 | G15: 69314 | H15: 69314 | I15: 104043 | J15: 95.3 | K15: 14000 | L15: 8 | M15: No | N15: =INDEX('State Mapping'!$B$2:$B$53,MATCH(B15,'State Mapping'!$A$2:$A$53,0)) -> New York | O15: =IFERROR(INDEX('State Premium Data'!$D$2:$D$53,MATCH(N15,'State Premium Data'!$A$2:$A$53,0)),"") -> 34733 | P15: =IFERROR(INDEX('State Premium Data'!$C$2:$C$53,MATCH(N15,'State Premium Data'!$A$2:$A$53,0)),"") -> 74504 | Q15: =IFERROR(K15/O15,"") -> 0.40307489 | R15: =IFERROR(I15-P15,"") -> 29539 | S15: =IFERROR(R15/P15,"") -> 0.39647536
A16: University of California-Los Angeles | B16: CA | C16: Los Angeles | D16: 9 | F16: 33475 | G16: 15203 | H16: 49403 | I16: 82511 | J16: 92.6 | K16: 14000 | L16: 43 | M16: Yes | N16: =INDEX('State Mapping'!$B$2:$B$53,MATCH(B16,'State Mapping'!$A$2:$A$53,0)) -> California | O16: =IFERROR(INDEX('State Premium Data'!$D$2:$D$53,MATCH(N16,'State Premium Data'!$A$2:$A$53,0)),"") -> 37475 | P16: =IFERROR(INDEX('State Premium Data'!$C$2:$C$53,MATCH(N16,'State Premium Data'!$A$2:$A$53,0)),"") -> 78278 | Q16: =IFERROR(K16/O16,"") -> 0.37358239 | R16: =IFERROR(I16-P16,"") -> 4233 | S16: =IFERROR(R16/P16,"") -> 0.054076497
A17: New York University | B17: NY | C17: New York | D17: 9.2 | E17: 1520 | F17: 28663 | G17: 62796 | H17: 62796 | I17: 82509 | J17: 88 | K17: 20500 | L17: 2 | M17: No | N17: =INDEX('State Mapping'!$B$2:$B$53,MATCH(B17,'State Mapping'!$A$2:$A$53,0)) -> New York | O17: =IFERROR(INDEX('State Premium Data'!$D$2:$D$53,MATCH(N17,'State Premium Data'!$A$2:$A$53,0)),"") -> 34733 | P17: =IFERROR(INDEX('State Premium Data'!$C$2:$C$53,MATCH(N17,'State Premium Data'!$A$2:$A$53,0)),"") -> 74504 | Q17: =IFERROR(K17/O17,"") -> 0.5902168 | R17: =IFERROR(I17-P17,"") -> 8005 | S17: =IFERROR(R17/P17,"") -> 0.1074439
A18: University of Southern California | B18: CA | C18: Los Angeles | D18: 9.8 | E18: 1495 | F18: 20443 | G18: 72097 | H18: 72097 | I18: 92498 | J18: 91.9 | K18: 18000 | L18: 2 | M18: No | N18: =INDEX('State Mapping'!$B$2:$B$53,MATCH(B18,'State Mapping'!$A$2:$A$53,0)) -> California | O18: =IFERROR(INDEX('State Premium Data'!$D$2:$D$53,MATCH(N18,'State Premium Data'!$A$2:$A$53,0)),"") -> 37475 | P18: =IFERROR(INDEX('State Premium Data'!$C$2:$C$53,MATCH(N18,'State Premium Data'!$A$2:$A$53,0)),"") -> 78278 | Q18: =IFERROR(K18/O18,"") -> 0.48032021 | R18: =IFERROR(I18-P18,"") -> 14220 | S18: =IFERROR(R18/P18,"") -> 0.18166024
A19: Emory University | B19: GA | C19: Atlanta | D19: 10.7 | E19: 1520 | F19: 7298 | G19: 64280 | H19: 64280 | I19: 80137 | J19: 91.4 | K19: 18250 | L19: 0 | M19: No | N19: =INDEX('State Mapping'!$B$2:$B$53,MATCH(B19,'State Mapping'!$A$2:$A$53,0)) -> Georgia | O19: =IFERROR(INDEX('State Premium Data'!$D$2:$D$53,MATCH(N19,'State Premium Data'!$A$2:$A$53,0)),"") -> 27365 | P19: =IFERROR(INDEX('State Premium Data'!$C$2:$C$53,MATCH(N19,'State Premium Data'!$A$2:$A$53,0)),"") -> 64185 | Q19: =IFERROR(K19/O19,"") -> 0.66691029 | R19: =IFERROR(I19-P19,"") -> 15952 | S19: =IFERROR(R19/P19,"") -> 0.24853159
A20: University of California-Berkeley | B20: CA | C20: Berkeley | D20: 11 | F20: 33068 | G20: 16347 | H20: 50547 | I20: 92446 | J20: 92.9 | K20: 13000 | L20: 43 | M20: Yes | N20: =INDEX('State Mapping'!$B$2:$B$53,MATCH(B20,'State Mapping'!$A$2:$A$53,0)) -> California | O20: =IFERROR(INDEX('State Premium Data'!$D$2:$D$53,MATCH(N20,'State Premium Data'!$A$2:$A$53,0)),"") -> 37475 | P20: =IFERROR(INDEX('State Premium Data'!$C$2:$C$53,MATCH(N20,'State Premium Data'!$A$2:$A$53,0)),"") -> 78278 | Q20: =IFERROR(K20/O20,"") -> 0.34689793 | R20: =IFERROR(I20-P20,"") -> 14168 | S20: =IFERROR(R20/P20,"") -> 0.18099594
A21: Boston University | B21: MA | C21: Boston | D21: 11.1 | E21: 1480 | F21: 18248 | G21: 68102 | H21: 68102 | I21: 83238 | J21: 89.3 | K21: 23250 | L21: 0 | M21: No | N21: =INDEX('State Mapping'!$B$2:$B$53,MATCH(B21,'State Mapping'!$A$2:$A$53,0)) -> Massachusetts | O21: =IFERROR(INDEX('State Premium Data'!$D$2:$D$53,MATCH(N21,'State Premium Data'!$A$2:$A$53,0)),"") -> 36224 | P21: =IFERROR(INDEX('State Premium Data'!$C$2:$C$53,MATCH(N21,'State Premium Data'!$A$2:$A$53,0)),"") -> 79985 | Q21: =IFERROR(K21/O21,"") -> 0.64183966 | R21: =IFERROR(I21-P21,"") -> 3253 | S21: =IFERROR(R21/P21,"") -> 0.040670126
A22: University of Notre Dame | B22: IN | C22: Notre Dame | D22: 11.3 | E22: 1520 | F22: 8818 | G22: 65025 | H22: 65025 | I22: 99980 | J22: 96 | K22: 19000 | L22: 0 | M22: No | N22: =INDEX('State Mapping'!$B$2:$B$53,MATCH(B22,'State Mapping'!$A$2:$A$53,0)) -> Indiana | O22: =IFERROR(INDEX('State Premium Data'!$D$2:$D$53,MATCH(N22,'State Premium Data'!$A$2:$A$53,0)),"") -> 21077 | P22: =IFERROR(INDEX('State Premium Data'!$C$2:$C$53,MATCH(N22,'State Premium Data'!$A$2:$A$53,0)),"") -> 60573 | Q22: =IFERROR(K22/O22,"") -> 0.90145656 | R22: =IFERROR(I22-P22,"") -> 39407 | S22: =IFERROR(R22/P22,"") -> 0.65057039
A23: Tufts University | B23: MA | C23: Medford | D23: 11.5 | E23: 1513 | F23: 7061 | G23: 70704 | H23: 70704 | I23: 83214 | J23: 93.4 | K23: 16250 | L23: 1 | M23: No | N23: =INDEX('State Mapping'!$B$2:$B$53,MATCH(B23,'State Mapping'!$A$2:$A$53,0)) -> Massachusetts | O23: =IFERROR(INDEX('State Premium Data'!$D$2:$D$53,MATCH(N23,'State Premium Data'!$A$2:$A$53,0)),"") -> 36224 | P23: =IFERROR(INDEX('State Premium Data'!$C$2:$C$53,MATCH(N23,'State Premium Data'!$A$2:$A$53,0)),"") -> 79985 | Q23: =IFERROR(K23/O23,"") -> 0.44859761 | R23: =IFERROR(I23-P23,"") -> 3229 | S23: =IFERROR(R23/P23,"") -> 0.040370069
A24: Carnegie Mellon University | B24: PA | C24: Pittsburgh | D24: 11.7 | E24: 1546 | F24: 7304 | G24: 66246 | H24: 66246 | I24: 114862 | J24: 93.3 | K24: 21750 | L24: 2 | M24: No | N24: =INDEX('State Mapping'!$B$2:$B$53,MATCH(B24,'State Mapping'!$A$2:$A$53,0)) -> Pennsylvania | O24: =IFERROR(INDEX('State Premium Data'!$D$2:$D$53,MATCH(N24,'State Premium Data'!$A$2:$A$53,0)),"") -> 25342 | P24: =IFERROR(INDEX('State Premium Data'!$C$2:$C$53,MATCH(N24,'State Premium Data'!$A$2:$A$53,0)),"") -> 65678 | Q24: =IFERROR(K24/O24,"") -> 0.85825902 | R24: =IFERROR(I24-P24,"") -> 49184 | S24: =IFERROR(R24/P24,"") -> 0.74886568
A25: Washington University in St Louis | B25: MO | C25: St. Louis | D25: 12.1 | E25: 1530 | F25: 7857 | G25: 65790 | H25: 65790 | I25: 86182 | J25: 94.3 | K25: 17500 | L25: 5 | M25: No | N25: =INDEX('State Mapping'!$B$2:$B$53,MATCH(B25,'State Mapping'!$A$2:$A$53,0)) -> Missouri | O25: =IFERROR(INDEX('State Premium Data'!$D$2:$D$53,MATCH(N25,'State Premium Data'!$A$2:$A$53,0)),"") -> 23998 | P25: =IFERROR(INDEX('State Premium Data'!$C$2:$C$53,MATCH(N25,'State Premium Data'!$A$2:$A$53,0)),"") -> 61418 | Q25: =IFERROR(K25/O25,"") -> 0.72922744 | R25: =IFERROR(I25-P25,"") -> 24764 | S25: =IFERROR(R25/P25,"") -> 0.40320427
A26: Georgetown University | B26: DC | C26: Washington | D26: 12.9 | E26: 1487 | F26: 7569 | G26: 68017 | H26: 68017 | I26: 103494 | J26: 94.5 | K26: 15500 | L26: 0 | M26: No | N26: =INDEX('State Mapping'!$B$2:$B$53,MATCH(B26,'State Mapping'!$A$2:$A$53,0)) -> District of Columbia | O26: =IFERROR(INDEX('State Premium Data'!$D$2:$D$53,MATCH(N26,'State Premium Data'!$A$2:$A$53,0)),"") -> 54913 | P26: =IFERROR(INDEX('State Premium Data'!$C$2:$C$53,MATCH(N26,'State Premium Data'!$A$2:$A$53,0)),"") -> 95628 | Q26: =IFERROR(K26/O26,"") -> 0.28226467 | R26: =IFERROR(I26-P26,"") -> 7866 | S26: =IFERROR(R26/P26,"") -> 0.082256243
A27: Tulane University of Louisiana | B27: LA | C27: New Orleans | D27: 14 | E27: 1448 | F27: 7767 | G27: 68678 | H27: 68678 | I27: 63268 | J27: 87.5 | K27: 20500 | L27: 0 | M27: No | N27: =INDEX('State Mapping'!$B$2:$B$53,MATCH(B27,'State Mapping'!$A$2:$A$53,0)) -> Louisiana | O27: =IFERROR(INDEX('State Premium Data'!$D$2:$D$53,MATCH(N27,'State Premium Data'!$A$2:$A$53,0)),"") -> 20975 | P27: =IFERROR(INDEX('State Premium Data'!$C$2:$C$53,MATCH(N27,'State Premium Data'!$A$2:$A$53,0)),"") -> 57107 | Q27: =IFERROR(K27/O27,"") -> 0.97735399 | R27: =IFERROR(I27-P27,"") -> 6161 | S27: =IFERROR(R27/P27,"") -> 0.1078852
A28: Georgia Institute of Technology-Main Campus | B28: GA | C28: Atlanta | D28: 14.1 | E28: 1480 | F28: 18785 | G28: 12058 | H28: 34484 | I28: 102772 | J28: 93.2 | K28: 21672 | L28: 0 | M28: No | N28: =INDEX('State Mapping'!$B$2:$B$53,MATCH(B28,'State Mapping'!$A$2:$A$53,0)) -> Georgia | O28: =IFERROR(INDEX('State Premium Data'!$D$2:$D$53,MATCH(N28,'State Premium Data'!$A$2:$A$53,0)),"") -> 27365 | P28: =IFERROR(INDEX('State Premium Data'!$C$2:$C$53,MATCH(N28,'State Premium Data'!$A$2:$A$53,0)),"") -> 64185 | Q28: =IFERROR(K28/O28,"") -> 0.79196053 | R28: =IFERROR(I28-P28,"") -> 38587 | S28: =IFERROR(R28/P28,"") -> 0.60118408
A29: University of North Carolina at Chapel Hill | B29: NC | C29: Chapel Hill | D29: 15.3 | E29: 1439 | F29: 20752 | G29: 8994 | H29: 41203 | I29: 72200 | J29: 91.6 | K29: 14000 | L29: 2 | M29: Yes | N29: =INDEX('State Mapping'!$B$2:$B$53,MATCH(B29,'State Mapping'!$A$2:$A$53,0)) -> North Carolina | O29: =IFERROR(INDEX('State Premium Data'!$D$2:$D$53,MATCH(N29,'State Premium Data'!$A$2:$A$53,0)),"") -> 25615 | P29: =IFERROR(INDEX('State Premium Data'!$C$2:$C$53,MATCH(N29,'State Premium Data'!$A$2:$A$53,0)),"") -> 62338 | Q29: =IFERROR(K29/O29,"") -> 0.54655475 | R29: =IFERROR(I29-P29,"") -> 9862 | S29: =IFERROR(R29/P29,"") -> 0.15820206
A30: University of Michigan-Ann Arbor | B30: MI | C30: Ann Arbor | D30: 15.6 | E30: 1465 | F30: 34177 | G30: 17736 | H30: 60946 | I30: 83648 | J30: 93.2 | K30: 19500 | L30: 1 | M30: Yes | N30: =INDEX('State Mapping'!$B$2:$B$53,MATCH(B30,'State Mapping'!$A$2:$A$53,0)) -> Michigan | O30: =IFERROR(INDEX('State Premium Data'!$D$2:$D$53,MATCH(N30,'State Premium Data'!$A$2:$A$53,0)),"") -> 27987 | P30: =IFERROR(INDEX('State Premium Data'!$C$2:$C$53,MATCH(N30,'State Premium Data'!$A$2:$A$53,0)),"") -> 64810 | Q30: =IFERROR(K30/O30,"") -> 0.69675206 | R30: =IFERROR(I30-P30,"") -> 18838 | S30: =IFERROR(R30/P30,"") -> 0.29066502
A31: Boston College | B31: MA | C31: Chestnut Hill | D31: 16.4 | E31: 1507 | F31: 10085 | G31: 70702 | H31: 70702 | I31: 103937 | J31: 90.9 | K31: 19000 | L31: 0 | M31: No | N31: =INDEX('State Mapping'!$B$2:$B$53,MATCH(B31,'State Mapping'!$A$2:$A$53,0)) -> Massachusetts | O31: =IFERROR(INDEX('State Premium Data'!$D$2:$D$53,MATCH(N31,'State Premium Data'!$A$2:$A$53,0)),"") -> 36224 | P31: =IFERROR(INDEX('State Premium Data'!$C$2:$C$53,MATCH(N31,'State Premium Data'!$A$2:$A$53,0)),"") -> 79985 | Q31: =IFERROR(K31/O31,"") -> 0.52451413 | R31: =IFERROR(I31-P31,"") -> 23952 | S31: =IFERROR(R31/P31,"") -> 0.29945615
A32: University of Virginia-Main Campus | B32: VA | C32: Charlottesville | D32: 16.8 | E32: 1480 | F32: 17597 | G32: 21803 | H32: 59512 | I32: 86863 | J32: 95.5 | K32: 17500 | L32: 0 | M32: Yes | N32: =INDEX('State Mapping'!$B$2:$B$53,MATCH(B32,'State Mapping'!$A$2:$A$53,0)) -> Virginia | O32: =IFERROR(INDEX('State Premium Data'!$D$2:$D$53,MATCH(N32,'State Premium Data'!$A$2:$A$53,0)),"") -> 33407 | P32: =IFERROR(INDEX('State Premium Data'!$C$2:$C$53,MATCH(N32,'State Premium Data'!$A$2:$A$53,0)),"") -> 74468 | Q32: =IFERROR(K32/O32,"") -> 0.52384231 | R32: =IFERROR(I32-P32,"") -> 12395 | S32: =IFERROR(R32/P32,"") -> 0.16644733
... A39: The University of Texas at Austin | B39: TX | C39: Austin | D39: 26.6 | E39: 1395 | F39: 42855 | G39: 11688 | H39: 44908 | I39: 75121 | J39: 88.3 | K39: 20500 | L39: 0 | M39: Yes | N39: =INDEX('State Mapping'!$B$2:$B$53,MATCH(B39,'State Mapping'!$A$2:$A$53,0)) -> Texas | O39: =IFERROR(INDEX('State Premium Data'!$D$2:$D$53,MATCH(N39,'State Premium Data'!$A$2:$A$53,0)),"") -> 29388 | P39: =IFERROR(INDEX('State Premium Data'!$C$2:$C$53,MATCH(N39,'State Premium Data'!$A$2:$A$53,0)),"") -> 66474 | Q39: =IFERROR(K39/O39,"") -> 0.69756363 | R39: =IFERROR(I39-P39,"") -> 8647 | S39: =IFERROR(R39/P39,"") -> 0.13008093
A40: University of California-San Diego | B40: CA | C40: La Jolla | D40: 26.7 | F40: 34948 | G40: 16758 | H40: 50958 | I40: 84943 | J40: 86.8 | K40: 15500 | L40: 43 | M40: Yes | N40: =INDEX('State Mapping'!$B$2:$B$53,MATCH(B40,'State Mapping'!$A$2:$A$53,0)) -> California | O40: =IFERROR(INDEX('State Premium Data'!$D$2:$D$53,MATCH(N40,'State Premium Data'!$A$2:$A$53,0)),"") -> 37475 | P40: =IFERROR(INDEX('State Premium Data'!$C$2:$C$53,MATCH(N40,'State Premium Data'!$A$2:$A$53,0)),"") -> 78278 | Q40: =IFERROR(K40/O40,"") -> 0.41360907 | R40: =IFERROR(I40-P40,"") -> 6665 | S40: =IFERROR(R40/P40,"") -> 0.085145252
A41: Villanova University | B41: PA | C41: Villanova | D41: 27 | E41: 1460 | F41: 6938 | G41: 67776 | H41: 67776 | I41: 100423 | J41: 92.1 | K41: 25874 | L41: 0 | M41: Yes | N41: =INDEX('State Mapping'!$B$2:$B$53,MATCH(B41,'State Mapping'!$A$2:$A$53,0)) -> Pennsylvania | O41: =IFERROR(INDEX('State Premium Data'!$D$2:$D$53,MATCH(N41,'State Premium Data'!$A$2:$A$53,0)),"") -> 25342 | P41: =IFERROR(INDEX('State Premium Data'!$C$2:$C$53,MATCH(N41,'State Premium Data'!$A$2:$A$53,0)),"") -> 65678 | Q41: =IFERROR(K41/O41,"") -> 1.0209928 | R41: =IFERROR(I41-P41,"") -> 34745 | S41: =IFERROR(R41/P41,"") -> 0.52902037
A42: University of California-Irvine | B42: CA | C42: Irvine | D42: 28.6 | F42: 30197 | G42: 15722 | H42: 49922 | I42: 80735 | J42: 86.4 | K42: 15000 | L42: 43 | M42: Yes | N42: =INDEX('State Mapping'!$B$2:$B$53,MATCH(B42,'State Mapping'!$A$2:$A$53,0)) -> California | O42: =IFERROR(INDEX('State Premium Data'!$D$2:$D$53,MATCH(N42,'State Premium Data'!$A$2:$A$53,0)),"") -> 37475 | P42: =IFERROR(INDEX('State Premium Data'!$C$2:$C$53,MATCH(N42,'State Premium Data'!$A$2:$A$53,0)),"") -> 78278 | Q42: =IFERROR(K42/O42,"") -> 0.40026684 | R42: =IFERROR(I42-P42,"") -> 2457 | S42: =IFERROR(R42/P42,"") -> 0.031388129
A43: California Polytechnic State University-San Luis Obispo | B43: CA | C43: San Luis Obispo | D43: 31.3 | F43: 21996 | G43: 13596 | H43: 34665 | I43: 90768 | J43: 85.7 | K43: 18500 | L43: 0 | M43: No | N43: =INDEX('State Mapping'!$B$2:$B$53,MATCH(B43,'State Mapping'!$A$2:$A$53,0)) -> California | O43: =IFERROR(INDEX('State Premium Data'!$D$2:$D$53,MATCH(N43,'State Premium Data'!$A$2:$A$53,0)),"") -> 37475 | P43: =IFERROR(INDEX('State Premium Data'!$C$2:$C$53,MATCH(N43,'State Premium Data'!$A$2:$A$53,0)),"") -> 78278 | Q43: =IFERROR(K43/O43,"") -> 0.49366244 | R43: =IFERROR(I43-P43,"") -> 12490 | S43: =IFERROR(R43/P43,"") -> 0.15955952
A44: University of California-Santa Barbara | B44: CA | C44: Santa Barbara | D44: 33 | F44: 23113 | G44: 16414 | H44: 50614 | I44: 74915 | J44: 84.2 | K44: 13993 | L44: 43 | M44: Yes | N44: =INDEX('State Mapping'!$B$2:$B$53,MATCH(B44,'State Mapping'!$A$2:$A$53,0)) -> California | O44: =IFERROR(INDEX('State Premium Data'!$D$2:$D$53,MATCH(N44,'State Premium Data'!$A$2:$A$53,0)),"") -> 37475 | P44: =IFERROR(INDEX('State Premium Data'!$C$2:$C$53,MATCH(N44,'State Premium Data'!$A$2:$A$53,0)),"") -> 78278 | Q44: =IFERROR(K44/O44,"") -> 0.3733956 | R44: =IFERROR(I44-P44,"") -> -3363 | S44: =IFERROR(R44/P44,"") -> -0.042962263
A45: Fairfield University | B45: CT | C45: Fairfield | D45: 33.3 | E45: 1335 | F45: 5373 | G45: 58350 | H45: 58350 | I45: 88794 | J45: 84.1 | K45: 26000 | L45: 0 | M45: No | N45: =INDEX('State Mapping'!$B$2:$B$53,MATCH(B45,'State Mapping'!$A$2:$A$53,0)) -> Connecticut | O45: =IFERROR(INDEX('State Premium Data'!$D$2:$D$53,MATCH(N45,'State Premium Data'!$A$2:$A$53,0)),"") -> 33855 | P45: =IFERROR(INDEX('State Premium Data'!$C$2:$C$53,MATCH(N45,'State Premium Data'!$A$2:$A$53,0)),"") -> 75975 | Q45: =IFERROR(K45/O45,"") -> 0.7679811 | R45: =IFERROR(I45-P45,"") -> 12819 | S45: =IFERROR(R45/P45,"") -> 0.16872655
A46: William & Mary | B46: VA | C46: Williamsburg | D46: 34.1 | E46: 1473 | F46: 7055 | G46: 25914 | H46: 51038 | I46: 73490 | J46: 90.2 | K46: 18500 | L46: 0 | M46: No | N46: =INDEX('State Mapping'!$B$2:$B$53,MATCH(B46,'State Mapping'!$A$2:$A$53,0)) -> Virginia | O46: =IFERROR(INDEX('State Premium Data'!$D$2:$D$53,MATCH(N46,'State Premium Data'!$A$2:$A$53,0)),"") -> 33407 | P46: =IFERROR(INDEX('State Premium Data'!$C$2:$C$53,MATCH(N46,'State Premium Data'!$A$2:$A$53,0)),"") -> 74468 | Q46: =IFERROR(K46/O46,"") -> 0.55377615 | R46: =IFERROR(I46-P46,"") -> -978 | S46: =IFERROR(R46/P46,"") -> -0.013133158
A47: Southern University and A & M College | B47: LA | C47: Baton Rouge | D47: 35.1 | E47: 942 | F47: 5519 | G47: 9922 | H47: 17272 | I47: 43371 | J47: 27.7 | K47: 29251 | L47: 0 | M47: No | N47: =INDEX('State Mapping'!$B$2:$B$53,MATCH(B47,'State Mapping'!$A$2:$A$53,0)) -> Louisiana | O47: =IFERROR(INDEX('State Premium Data'!$D$2:$D$53,MATCH(N47,'State Premium Data'!$A$2:$A$53,0)),"") -> 20975 | P47: =IFERROR(INDEX('State Premium Data'!$C$2:$C$53,MATCH(N47,'State Premium Data'!$A$2:$A$53,0)),"") -> 57107 | Q47: =IFERROR(K47/O47,"") -> 1.394565 | R47: =IFERROR(I47-P47,"") -> -13736 | S47: =IFERROR(R47/P47,"") -> -0.24053093
...

Sheet 3-School Comparison
A1: Harvard vs. Princeton vs. BYU — Debt & Earnings Comparison
A2: Debt-to-premium ratio and real vs. state-baseline earnings, benchmarked against the national average across all 200 schools.
A4: Metric | B4: Harvard University | C4: Princeton University | D4: Brigham Young University | E4: National Average (200 schools)
A5: Median Debt ($) | B5: =INDEX('College Data'!$K:$K,MATCH(B$4,'College Data'!$A:$A,0)) -> 14000 | C5: =INDEX('College Data'!$K:$K,MATCH(C$4,'College Data'!$A:$A,0)) -> 10320 | D5: =INDEX('College Data'!$K:$K,MATCH(D$4,'College Data'!$A:$A,0)) -> 11069 | E5: =AVERAGE('College Data'!$K$2:$K$201) -> 19824.92
A6: State College Wage Premium ($) | B6: =INDEX('College Data'!$O:$O,MATCH(B$4,'College Data'!$A:$A,0)) -> 36224 | C6: =INDEX('College Data'!$O:$O,MATCH(C$4,'College Data'!$A:$A,0)) -> 38586 | D6: =INDEX('College Data'!$O:$O,MATCH(D$4,'College Data'!$A:$A,0)) -> 21307 | E6: =AVERAGE('College Data'!$O$2:$O$201) -> 29759.19
A7: Debt-to-Premium Ratio | B7: =INDEX('College Data'!$Q:$Q,MATCH(B$4,'College Data'!$A:$A,0)) -> 0.3864841 | C7: =INDEX('College Data'!$Q:$Q,MATCH(C$4,'College Data'!$A:$A,0)) -> 0.26745452 | D7: =INDEX('College Data'!$Q:$Q,MATCH(D$4,'College Data'!$A:$A,0)) -> 0.51950063 | E7: =AVERAGE('College Data'!$Q$2:$Q$201) -> 0.7071609
A8: School Median Earnings, 10yr ($) | B8: =INDEX('College Data'!$I:$I,MATCH(B$4,'College Data'!$A:$A,0)) -> 101817 | C8: =INDEX('College Data'!$I:$I,MATCH(C$4,'College Data'!$A:$A,0)) -> 110066 | D8: =INDEX('College Data'!$I:$I,MATCH(D$4,'College Data'!$A:$A,0)) -> 75790 | E8: =AVERAGE('College Data'!$I$2:$I$201) -> 70114
A9: State Baseline Earnings - Bachelor's ($) | B9: =INDEX('College Data'!$P:$P,MATCH(B$4,'College Data'!$A:$A,0)) -> 79985 | C9: =INDEX('College Data'!$P:$P,MATCH(C$4,'College Data'!$A:$A,0)) -> 80114 | D9: =INDEX('College Data'!$P:$P,MATCH(D$4,'College Data'!$A:$A,0)) -> 63247 | E9: =AVERAGE('College Data'!$P$2:$P$201) -> 68800.67
A10: Real Earnings vs. State Baseline ($) | B10: =INDEX('College Data'!$R:$R,MATCH(B$4,'College Data'!$A:$A,0)) -> 21832 | C10: =INDEX('College Data'!$R:$R,MATCH(C$4,'College Data'!$A:$A,0)) -> 29952 | D10: =INDEX('College Data'!$R:$R,MATCH(D$4,'College Data'!$A:$A,0)) -> 12543 | E10: =AVERAGE('College Data'!$R$2:$R$201) -> 1313.33
A11: Real Earnings vs. State Baseline (%) | B11: =INDEX('College Data'!$S:$S,MATCH(B$4,'College Data'!$A:$A,0)) -> 0.27295118 | C11: =INDEX('College Data'!$S:$S,MATCH(C$4,'College Data'!$A:$A,0)) -> 0.37386724 | D11: =INDEX('College Data'!$S:$S,MATCH(D$4,'College Data'!$A:$A,0)) -> 0.19831771 | E11: =AVERAGE('College Data'!$S$2:$S$201) -> 0.023803204
A13: Legend
A14: Green = better than national average
A15: Red = worse than national average
A16: (For debt-to-premium, lower is better. For earnings-vs-baseline, higher is better.)
A18: Definitions
A19: Debt-to-Premium Ratio = Median Debt ÷ State College Wage Premium ($). Lower means the debt load is small relative to the wage boost a bachelor's degree earns in that state.
A20: State College Wage Premium ($) = state-level median bachelor's earnings minus median high-school-only earnings (college_premium_by_state.csv, Source: US Census / BEA).
A21: Real Earnings vs. State Baseline = School's Median Earnings (10yr) minus the state's average bachelor's-holder earnings. Shows whether a school's grads out-earn the typical bachelor's degree holder in that state.
A22: National Average = simple average across all 200 schools in college-data.csv, each matched to its state's premium data by state.
A24: Sources: college-data.csv (College Scorecard/US Dept of Education, Nobel Prize API, NCAA); college_premium_by_state.csv (US Census, Bureau of Economic Analysis).

Sheet Debt-to-Premium Ratio
A1: Debt-to-Premium Ratio
A2: Median Debt ÷ State College Wage Premium. Lower means less debt relative to the wage boost a bachelor's degree earns in that state.

Sheet Real Earnings vs Baseline
A1: Real Earnings vs. State Baseline ($)
A2: School's Median Earnings (10yr) minus the state's average bachelor's-holder earnings — how much each school's grads out-earn the typical bachelor's degree holder in that state.
